Workbook

Sheet Start Here
A1: Career Interest Assessment — All Life Stages (Final)
A3: How this workbook works
A4: Each of the 6 life-stage tabs contains all 10 quiz sets stacked in ONE sheet (150 rows: 10 sets x 15 questions). Every question shows 5 of the 8 career-cluster options - which 5 rotates question to question, so all 8 clusters still get fair, tracked coverage across a 15-question set.
A6: How to take it
A7: 1. Go to your life-stage tab. Pick ONE set number (1-10) in the blue selector cell near the top.
A8: 2. For that set's 15 rows only, type the number (1-5) of your chosen option into the 'Your Answer' column.
A9: 3. The Live Results and Top 3 Career Fields boxes below the selector update automatically.
A11: Why 10 sets?
A12: A single 15-question quiz gives a useful first read. For a more stable picture, try 2-3 different sets on different days and see which clusters keep showing up in the Top 3.
A14: Framework basis by group
A16: Group | B16: Framework Basis
A17: Class 6-8 (Ages 11-13) | B17: Junior RIASEC
A18: Class 9-10 (Ages 14-15) | B18: Holland's SDS (Self-Directed Search) style
A19: Class 11-12 (Ages 16-17) | B19: Holland's SDS / Strong Interest Inventory style
A20: Graduate (Ages 18-21) | B20: Holland's SDS / Strong Interest Inventory style
A21: Early Career (Ages 21-25) | B21: Strong Interest Inventory / O*NET style
A22: Professionals (Ages 25-55) | B22: O*NET Interest Profiler style (for career pivots)
A24: A note on accuracy
A25: No short quiz can be 100% accurate at identifying a person's career interest - interests, especially at younger ages, are still forming. This assessment follows the same internal-consistency principles as real interest inventories (RIASEC, SDS, Strong Interest Inventory, O*NET Interest Profiler), so results are a meaningful, well-grounded starting point for exploration and conversation - not a final verdict.

Sheet Answer Key
A1: Answer Key — Option Letter to Career Cluster
A3: Option Letter | B3: Career Cluster
A4: A | B4: Engineering & Construction
A5: B | B5: Information Technology
A6: C | B6: Health Science
A7: D | B7: Arts, Media & Design
A8: E | B8: Business & Marketing
A9: F | B9: Human & Public Services
A10: G | B10: Science, Nature & Agriculture
A11: H | B11: Sports, Hospitality & Lifestyle

Sheet Career Clusters & Pathways
A1: The 8 Career Clusters and Sample Pathways
A3: Letter | B3: Cluster | C3: Maps to (detailed clusters in All info sheet) | D3: Sample Career Pathways
A4: A | B4: Engineering & Construction | C4: Architecture & Construction, Manufacturing, Energy, Transportation, Distribution & Logistics | D4: Civil / Structural Engineer, Construction Manager, Industrial / Manufacturing Engineer, Renewable Energy Engineer, Supply Chain / Logistics Manager
A5: B | B5: Information Technology | C5: Information Technology | D5: Software Developer, Data Scientist / Analyst, Cybersecurity Analyst, Cloud / DevOps Engineer, UI/UX Designer
A6: C | B6: Health Science | C6: Health Science | D6: Doctor / Dentist, Nurse, Physiotherapist / Allied Health, Pharmacist / Biotech Researcher, Psychologist / Counselor
A7: D | B7: Arts, Media & Design | C7: Arts, Audio/Video Technology & Communications, Media & Entertainment, Fashion & Design | D7: Graphic / UX Designer, Film & Video Producer, Animator, Fashion Designer, Journalist / Content Creator
A8: E | B8: Business & Marketing | C8: Business Management & Administration, Marketing, Sales & Service, Finance | D8: Management Consultant, Digital Marketer, Sales / Business Development, Financial Analyst, Entrepreneur / Founder
A9: F | B9: Human & Public Services | C9: Education & Training, Government & Public Administration, Human Services, Law, Public Safety, Corrections & Security | D9: Teacher, Social Worker / Counselor, Policy Analyst, Lawyer, Police / Public Safety Officer
A10: G | B10: Science, Nature & Agriculture | C10: Science, Technology, Engineering & Mathematics (STEM), Agriculture, Food & Natural Resources | D10: Research Scientist, Agricultural Scientist, Environmental Engineer, Biotechnologist, Robotics / AI Researcher
A11: H | B11: Sports, Hospitality & Lifestyle | C11: Hospitality & Tourism, Sports & Recreation | D11: Hotel / Events Manager, Sports Coach / Trainer, Travel Consultant, Sports Scientist / Physiotherapist, Chef / Culinary Professional

Sheet 6-8 Quiz
A1: Class 6-8 (Ages 11-13) — Career Interest Quiz (10 Sets x 15 Questions)
A2: Framework basis: Junior RIASEC
A4: Which set are you taking? | B4: Set 1 | C4: (pick one set, then answer only that set's 15 rows below)
A6: Set | B6: Q# | C6: Theme | D6: Scenario | E6: Option 1 | F6: Option 2 | G6: Option 3 | H6: Option 4 | I6: Option 5 | J6: t1 | K6: t2 | L6: t3 | M6: t4 | N6: t5 | O6: Your Answer (1-5) | P6: Letter | R6: Letter | S6: Score
A7: Set 1 | B7: Q1 | C7: Free time choice | D7: If you had a free Saturday, what would you most want to do? | E7: 1) Draw, paint, write, or make music | F7: 2) Set up a little stall or sell something to friends | G7: 3) Hang out and help organize things with friends | H7: 4) Explore outside, collect bugs/rocks, or do a mini experiment | I7: 5) Play or watch sports, or plan a fun outing | J7: D | K7: E | L7: F | M7: G | N7: H | P7: =IF(O7="","",INDEX(J7:N7,1,O7)) | R7: A | S7: =$D$160+0.0000008 -> 8e-07
A8: Set 1 | B8: Q2 | C8: Favorite subject | D8: Which school subject sounds most exciting to you? | E8: 1) Woodwork, shop class, or hands-on building projects | F8: 2) Computer class or coding | G8: 3) Biology or health class | H8: 4) Science lab or experiments | I8: 5) Physical Education or outdoor activities | J8: A | K8: B | L8: C | M8: G | N8: H | P8: =IF(O8="","",INDEX(J8:N8,1,O8)) | R8: B | S8: =$D$161+0.0000007 -> 7e-07
A9: Set 1 | B9: Q3 | C9: Dream job for a day | D9: If you could have any superpower job for a day, which would you pick? | E9: 1) Software Developer or Game Designer | F9: 2) Doctor or Physiotherapist | G9: 3) Animator or Musician | H9: 4) CEO or Marketing Manager | I9: 5) Teacher or Social Worker | J9: B | K9: C | L9: D | M9: E | N9: F | P9: =IF(O9="","",INDEX(J9:N9,1,O9)) | R9: C | S9: =$D$162+0.0000006 -> 6e-07
A10: Set 1 | B10: Q4 | C10: Group project role | D10: In a group project, what role do you naturally take? | E10: 1) The one who builds the physical model | F10: 2) The one who leads the group and presents | G10: 3) The one who makes sure everyone feels included | H10: 4) The one who studies the facts and details carefully | I10: 5) The one who keeps the energy up and organizes fun breaks | J10: A | K10: E | L10: F | M10: G | N10: H | P10: =IF(O10="","",INDEX(J10:N10,1,O10)) | R10: D | S10: =$D$163+0.0000005 -> 5e-07
A11: Set 1 | B11: Q5 | C11: Dream camp or club | D11: Which of these sounds like the best summer camp? | E11: 1) Robotics & Engineering Camp | F11: 2) Coding & Game Development Camp | G11: 3) Junior Doctor / Health Camp | H11: 4) Music, Art & Theatre Camp | I11: 5) Sports Camp or Adventure Camp | J11: A | K11: B | L11: C | M11: D | N11: H | P11: =IF(O11="","",INDEX(J11:N11,1,O11)) | R11: E | S11: =$D$164+0.0000004 -> 4e-07
A12: Set 1 | B12: Q6 | C12: Game or app style | D12: What kind of video games or apps do you enjoy most? | E12: 1) Health or hospital simulation games | F12: 2) Story-rich, creative games | G12: 3) City-builder or tycoon/business games | H12: 4) Games where you help or team up with others | I12: 5) Nature, survival, or discovery games | J12: C | K12: D | L12: E | M12: F | N12: G | P12: =IF(O12="","",INDEX(J12:N12,1,O12)) | R12: F | S12: =$D$165+0.0000003 -> 3e-07
A13: Set 1 | B13: Q7 | C13: Story or movie style | D13: What kind of stories/movies do you enjoy most? | E13: 1) Action/adventure with cool inventions | F13: 2) Sci-fi or tech-related stories | G13: 3) Stories about friendship, community, or justice | H13: 4) Stories about nature, space, or discovery | I13: 5) Stories about sports or travel adventures | J13: A | K13: B | L13: F | M13: G | N13: H | P13: =IF(O13="","",INDEX(J13:N13,1,O13)) | R13: G | S13: =$D$166+0.0000002 -> 2e-07
A14: Set 1 | B14: Q8 | C14: Career fair booth | D14: If your class did a mock 'career fair,' which booth excites you most? | E14: 1) Engineering/robotics booth | F14: 2) Software company booth | G14: 3) Hospital/medical booth | H14: 4) Art & music school booth | I14: 5) Startup/business booth | J14: A | K14: B | L14: C | M14: D | N14: E | P14: =IF(O14="","",INDEX(J14:N14,1,O14)) | R14: H | S14: =$D$167+0.0000001 -> 1e-07
A15: Set 1 | B15: Q9 | C15: Helping someone | D15: How do you feel about helping someone who's hurt or unwell? | E15: 1) I'd want to comfort them creatively, like drawing or writing for them | F15: 2) I'd organize help or support from others | G15: 3) I'd sit with them and make sure they're not alone | H15: 4) I'd want to understand exactly what happened and why | I15: 5) I'd try to cheer them up with a fun distraction | J15: D | K15: E | L15: F | M15: G | N15: H | P15: =IF(O15="","",INDEX(J15:N15,1,O15))
A16: Set 1 | B16: Q10 | C16: Making something | D16: Pick a weekend activity you'd enjoy making or building. | E16: 1) Assembling a model kit or gadget | F16: 2) Coding a small game or app | G16: 3) Making a first-aid kit or health poster | H16: 4) Doing a mini science experiment | I16: 5) Planning a fun activity or game for others | J16: A | K16: B | L16: C | M16: G | N16: H | P16: =IF(O16="","",INDEX(J16:N16,1,O16))
A17: Set 1 | B17: Q11 | C17: Wanting to be known for | D17: What would you like to be known for when you grow up? | E17: 1) "Created a cool app or game" | F17: 2) "Helped save lives" | G17: 3) "Made beautiful art or music" | H17: 4) "Built a successful company" | I17: 5) "Helped people or the community" | J17: B | K17: C | L17: D | M17: E | N17: F | P17: =IF(O17="","",INDEX(J17:N17,1,O17))
A18: Set 1 | B18: Q12 | C18: Problem you'd like to solve | D18: Which problem sounds most interesting to solve? | E18: 1) How to build something stronger or faster | F18: 2) How to make or grow money | G18: 3) How to make life fairer or better for people | H18: 4) How the natural world works | I18: 5) How to make an experience more fun or exciting | J18: A | K18: E | L18: F | M18: G | N18: H | P18: =IF(O18="","",INDEX(J18:N18,1,O18))
A19: Set 1 | B19: Q13 | C19: A day in your life at 25 | D19: Imagine yourself at age 25 — what does your workday look like? | E19: 1) Working with machines, tools, or at a construction site | F19: 2) Coding, building apps, or fixing tech systems | G19: 3) Working in a hospital, clinic, or lab | H19: 4) Creating art, music, films, or writing | I19: 5) Coaching sports or working in hotels/travel | J19: A | K19: B | L19: C | M19: D | N19: H | P19: =IF(O19="","",INDEX(J19:N19,1,O19))
A20: Set 1 | B20: Q14 | C20: When something breaks | D20: Imagine something in your house stops working, what do you want to do? | E20: 1) I check if anyone's safety was affected | F20: 2) I turn it into an art project (upcycling) | G20: 3) I figure out if it's worth repairing or replacing | H20: 4) I ask who else needs to know or help | I20: 5) I want to understand exactly why it broke | J20: C | K20: D | L20: E | M20: F | N20: G | P20: =IF(O20="","",INDEX(J20:N20,1,O20))
A21: Set 1 | B21: Q15 | C21: Role in a team activity | D21: In a class team activity, what part do you enjoy most? | E21: 1) I like building or setting up the physical stuff | F21: 2) I like handling the tech or digital tools | G21: 3) I like making sure everyone feels welcome | H21: 4) I like figuring out the facts or rules | I21: 5) I like keeping the energy and fun going | J21: A | K21: B | L21: F | M21: G | N21: H | P21: =IF(O21="","",INDEX(J21:N21,1,O21))
A22: Set 2 | B22: Q1 | C22: Free time choice | D22: You have an unplanned afternoon after school. What sounds most fun? | E22: 1) Draw, paint, write, or make music | F22: 2) Set up a little stall or sell something to friends | G22: 3) Hang out and help organize things with friends | H22: 4) Explore outside, collect bugs/rocks, or do a mini experiment | I22: 5) Play or watch sports, or plan a fun outing | J22: D | K22: E | L22: F | M22: G | N22: H | P22: =IF(O22="","",INDEX(J22:N22,1,O22))
A23: Set 2 | B23: Q2 | C23: Favorite subject | D23: If you had to pick just one subject to study all day, which would it be? | E23: 1) Woodwork, shop class, or hands-on building projects | F23: 2) Computer class or coding | G23: 3) Biology or health class | H23: 4) Science lab or experiments | I23: 5) Physical Education or outdoor activities | J23: A | K23: B | L23: C | M23: G | N23: H | P23: =IF(O23="","",INDEX(J23:N23,1,O23))
A24: Set 2 | B24: Q3 | C24: Dream job for a day | D24: If you could shadow any professional for a day, who would you choose? | E24: 1) Software Developer or Game Designer | F24: 2) Doctor or Physiotherapist | G24: 3) Animator or Musician | H24: 4) CEO or Marketing Manager | I24: 5) Teacher or Social Worker | J24: B | K24: C | L24: D | M24: E | N24: F | P24: =IF(O24="","",INDEX(J24:N24,1,O24))
A25: Set 2 | B25: Q4 | C25: Group project role | D25: When your class is split into teams, what job do you usually end up doing? | E25: 1) The one who builds the physical model | F25: 2) The one who leads the group and presents | G25: 3) The one who makes sure everyone feels included | H25: 4) The one who studies the facts and details carefully | I25: 5) The one who keeps the energy up and organizes fun breaks | J25: A | K25: E | L25: F | M25: G | N25: H | P25: =IF(O25="","",INDEX(J25:N25,1,O25))
A26: Set 2 | B26: Q5 | C26: Dream camp or club | D26: If your school offered one special weekend workshop, which would you join? | E26: 1) Robotics & Engineering Camp | F26: 2) Coding & Game Development Camp | G26: 3) Junior Doctor / Health Camp | H26: 4) Music, Art & Theatre Camp | I26: 5) Sports Camp or Adventure Camp | J26: A | K26: B | L26: C | M26: D | N26: H | P26: =IF(O26="","",INDEX(J26:N26,1,O26))
... A156: Set 10 | B156: Q15 | C156: Role in a team activity | D156: During a school fair, which job would you sign up for? | E156: 1) I like building or setting up the physical stuff | F156: 2) I like handling the tech or digital tools | G156: 3) I like making sure everyone feels welcome | H156: 4) I like figuring out the facts or rules | I156: 5) I like keeping the energy and fun going | J156: A | K156: B | L156: F | M156: G | N156: H | P156: =IF(O156="","",INDEX(J156:N156,1,O156))
A158: LIVE RESULTS FOR YOUR SELECTED SET
A159: Cluster (Letter) | B159: Times Chosen | C159: Times It Appeared | D159: Your Score %
A160: A | B160: =COUNTIFS($A$7:$A$156,B4,$P$7:$P$156,"A") -> 0 | C160: =SUMPRODUCT((J7:J156="A")*(A7:A156=B4)+(K7:K156="A")*(A7:A156=B4)+(L7:L156="A")*(A7:A156=B4)+(M7:M156="A")*(A7:A156=B4)+(N7:N156="A")*(A7:A156=B4)) -> 9 | D160: =IFERROR(ROUND(B160/C160*100,0),0) -> 0
A161: B | B161: =COUNTIFS($A$7:$A$156,B4,$P$7:$P$156,"B") -> 0 | C161: =SUMPRODUCT((J7:J156="B")*(A7:A156=B4)+(K7:K156="B")*(A7:A156=B4)+(L7:L156="B")*(A7:A156=B4)+(M7:M156="B")*(A7:A156=B4)+(N7:N156="B")*(A7:A156=B4)) -> 9 | D161: =IFERROR(ROUND(B161/C161*100,0),0) -> 0
A162: C | B162: =COUNTIFS($A$7:$A$156,B4,$P$7:$P$156,"C") -> 0 | C162: =SUMPRODUCT((J7:J156="C")*(A7:A156=B4)+(K7:K156="C")*(A7:A156=B4)+(L7:L156="C")*(A7:A156=B4)+(M7:M156="C")*(A7:A156=B4)+(N7:N156="C")*(A7:A156=B4)) -> 9 | D162: =IFERROR(ROUND(B162/C162*100,0),0) -> 0
A163: D | B163: =COUNTIFS($A$7:$A$156,B4,$P$7:$P$156,"D") -> 0 | C163: =SUMPRODUCT((J7:J156="D")*(A7:A156=B4)+(K7:K156="D")*(A7:A156=B4)+(L7:L156="D")*(A7:A156=B4)+(M7:M156="D")*(A7:A156=B4)+(N7:N156="D")*(A7:A156=B4)) -> 9 | D163: =IFERROR(ROUND(B163/C163*100,0),0) -> 0
A164: E | B164: =COUNTIFS($A$7:$A$156,B4,$P$7:$P$156,"E") -> 0 | C164: =SUMPRODUCT((J7:J156="E")*(A7:A156=B4)+(K7:K156="E")*(A7:A156=B4)+(L7:L156="E")*(A7:A156=B4)+(M7:M156="E")*(A7:A156=B4)+(N7:N156="E")*(A7:A156=B4)) -> 9 | D164: =IFERROR(ROUND(B164/C164*100,0),0) -> 0
A165: F | B165: =COUNTIFS($A$7:$A$156,B4,$P$7:$P$156,"F") -> 0 | C165: =SUMPRODUCT((J7:J156="F")*(A7:A156=B4)+(K7:K156="F")*(A7:A156=B4)+(L7:L156="F")*(A7:A156=B4)+(M7:M156="F")*(A7:A156=B4)+(N7:N156="F")*(A7:A156=B4)) -> 10 | D165: =IFERROR(ROUND(B165/C165*100,0),0) -> 0
A166: G | B166: =COUNTIFS($A$7:$A$156,B4,$P$7:$P$156,"G") -> 0 | C166: =SUMPRODUCT((J7:J156="G")*(A7:A156=B4)+(K7:K156="G")*(A7:A156=B4)+(L7:L156="G")*(A7:A156=B4)+(M7:M156="G")*(A7:A156=B4)+(N7:N156="G")*(A7:A156=B4)) -> 10 | D166: =IFERROR(ROUND(B166/C166*100,0),0) -> 0
A167: H | B167: =COUNTIFS($A$7:$A$156,B4,$P$7:$P$156,"H") -> 0 | C167: =SUMPRODUCT((J7:J156="H")*(A7:A156=B4)+(K7:K156="H")*(A7:A156=B4)+(L7:L156="H")*(A7:A156=B4)+(M7:M156="H")*(A7:A156=B4)+(N7:N156="H")*(A7:A156=B4)) -> 10 | D167: =IFERROR(ROUND(B167/C167*100,0),0) -> 0
A169: YOUR TOP 3 CAREER FIELD MATCHES
A170: Rank | B170: Career Field | C170: Match | D170: Sample Pathways
A171: 1 | B171: =INDEX('Career Clusters & Pathways'!$B$4:$B$11,MATCH(U171,'Career Clusters & Pathways'!$A$4:$A$11,0)) -> Engineering & Construction | C171: =ROUND(LARGE($S$7:$S$14,1),0)&"%" -> 0% | D171: =INDEX('Career Clusters & Pathways'!$D$4:$D$11,MATCH(U171,'Career Clusters & Pathways'!$A$4:$A$11,0)) -> Civil / Structural Engineer, Construction Manager, Industrial / Manufacturing Engineer, Renewable Energy Engineer, Supply Chain / Logistics Manager | U171: =INDEX($R$7:$R$14,MATCH(LARGE($S$7:$S$14,1),$S$7:$S$14,0)) -> A
A172: 2 | B172: =INDEX('Career Clusters & Pathways'!$B$4:$B$11,MATCH(U172,'Career Clusters & Pathways'!$A$4:$A$11,0)) -> Information Technology | C172: =ROUND(LARGE($S$7:$S$14,2),0)&"%" -> 0% | D172: =INDEX('Career Clusters & Pathways'!$D$4:$D$11,MATCH(U172,'Career Clusters & Pathways'!$A$4:$A$11,0)) -> Software Developer, Data Scientist / Analyst, Cybersecurity Analyst, Cloud / DevOps Engineer, UI/UX Designer | U172: =INDEX($R$7:$R$14,MATCH(LARGE($S$7:$S$14,2),$S$7:$S$14,0)) -> B
A173: 3 | B173: =INDEX('Career Clusters & Pathways'!$B$4:$B$11,MATCH(U173,'Career Clusters & Pathways'!$A$4:$A$11,0)) -> Health Science | C173: =ROUND(LARGE($S$7:$S$14,3),0)&"%" -> 0% | D173: =INDEX('Career Clusters & Pathways'!$D$4:$D$11,MATCH(U173,'Career Clusters & Pathways'!$A$4:$A$11,0)) -> Doctor / Dentist, Nurse, Physiotherapist / Allied Health, Pharmacist / Biotech Researcher, Psychologist / Counselor | U173: =INDEX($R$7:$R$14,MATCH(LARGE($S$7:$S$14,3),$S$7:$S$14,0)) -> C
...

Sheet 9-10 Quiz
A1: Class 9-10 (Ages 14-15) — Career Interest Quiz (10 Sets x 15 Questions)
A2: Framework basis: Holland's SDS (Self-Directed Search) style
A4: Which set are you taking? | B4: Set 1 | C4: (pick one set, then answer only that set's 15 rows below)
A6: Set | B6: Q# | C6: Theme | D6: Scenario | E6: Option 1 | F6: Option 2 | G6: Option 3 | H6: Option 4 | I6: Option 5 | J6: t1 | K6: t2 | L6: t3 | M6: t4 | N6: t5 | O6: Your Answer (1-5) | P6: Letter | R6: Letter | S6: Score
A7: Set 1 | B7: Q1 | C7: Free time choice | D7: You've got a free Saturday with no homework due. What pulls you in most? | E7: 1) Sketch, write lyrics, or edit a short video | F7: 2) Plan a small sale or fundraiser with friends | G7: 3) Organise a hangout or help a junior with homework | H7: 4) Watch a science documentary or try a home experiment | I7: 5) Play a match, watch sport, or plan a weekend trip | J7: D | K7: E | L7: F | M7: G | N7: H | P7: =IF(O7="","",INDEX(J7:N7,1,O7)) | R7: A | S7: =$D$160+0.0000008 -> 8e-07
A8: Set 1 | B8: Q2 | C8: Favorite subject | D8: Which school subject sounds most exciting to you? | E8: 1) Workshop, hands-on lab, or technical drawing | F8: 2) Computer Science or coding electives | G8: 3) Biology or Health Science | H8: 4) Physics/Chemistry lab or environmental science | I8: 5) Physical Education or sports coaching sessions | J8: A | K8: B | L8: C | M8: G | N8: H | P8: =IF(O8="","",INDEX(J8:N8,1,O8)) | R8: B | S8: =$D$161+0.0000007 -> 7e-07
A9: Set 1 | B9: Q3 | C9: Dream job for a day | D9: If you could shadow any professional for a day, who would you choose? | E9: 1) Mobile App Developer or Game Designer | F9: 2) Doctor or Sports Physiotherapist | G9: 3) Animator, Musician, or Content Creator | H9: 4) Entrepreneur or Marketing Manager | I9: 5) Teacher or Counselor | J9: B | K9: C | L9: D | M9: E | N9: F | P9: =IF(O9="","",INDEX(J9:N9,1,O9)) | R9: C | S9: =$D$162+0.0000006 -> 6e-07
A10: Set 1 | B10: Q4 | C10: Group project role | D10: In a group project, what role do you naturally take? | E10: 1) The one who builds or assembles the physical model | F10: 2) The one who leads, pitches, and presents | G10: 3) The one who makes sure everyone is included and heard | H10: 4) The one who researches facts and checks accuracy | I10: 5) The one who organizes logistics and keeps energy up | J10: A | K10: E | L10: F | M10: G | N10: H | P10: =IF(O10="","",INDEX(J10:N10,1,O10)) | R10: D | S10: =$D$163+0.0000005 -> 5e-07
A11: Set 1 | B11: Q5 | C11: Dream club or program | D11: Which of these sounds like the club you'd want to join this year? | E11: 1) Weekend Robotics or Automotive Workshop | F11: 2) Coding Bootcamp or Game Development Club | G11: 3) Junior Medical / First-Responder Program | H11: 4) Music, Art, or Film-making Workshop | I11: 5) Sports Academy Trial or Adventure Camp | J11: A | K11: B | L11: C | M11: D | N11: H | P11: =IF(O11="","",INDEX(J11:N11,1,O11)) | R11: E | S11: =$D$164+0.0000004 -> 4e-07
A12: Set 1 | B12: Q6 | C12: App or game style | D12: What kind of apps or games do you use the most? | E12: 1) Fitness or health-tracking apps | F12: 2) Story-driven or creative design apps | G12: 3) Business simulation or trading apps | H12: 4) Social or team-collaboration apps | I12: 5) Nature, survival, or exploration games | J12: C | K12: D | L12: E | M12: F | N12: G | P12: =IF(O12="","",INDEX(J12:N12,1,O12)) | R12: F | S12: =$D$165+0.0000003 -> 3e-07
A13: Set 1 | B13: Q7 | C13: Story or show style | D13: What kind of shows or movies do you enjoy most? | E13: 1) Action/adventure with cool inventions or vehicles | F13: 2) Sci-fi, hacking, or tech-thriller stories | G13: 3) Stories about justice, activism, or community | H13: 4) Stories about space, nature, or discovery | I13: 5) Sports dramas or travel adventure stories | J13: A | K13: B | L13: F | M13: G | N13: H | P13: =IF(O13="","",INDEX(J13:N13,1,O13)) | R13: G | S13: =$D$166+0.0000002 -> 2e-07
A14: Set 1 | B14: Q8 | C14: Career fair booth | D14: If your school ran a mock 'career fair,' which booth excites you most? | E14: 1) Engineering & robotics booth | F14: 2) Software/tech company booth | G14: 3) Hospital/medical college booth | H14: 4) Art, music, or film school booth | I14: 5) Startup or business-school booth | J14: A | K14: B | L14: C | M14: D | N14: E | P14: =IF(O14="","",INDEX(J14:N14,1,O14)) | R14: H | S14: =$D$167+0.0000001 -> 1e-07
A15: Set 1 | B15: Q9 | C15: Helping someone | D15: A classmate gets hurt or falls sick at school. What's your instinct? | E15: 1) I'd write, draw, or create something to comfort them | F15: 2) I'd rally friends or resources to help quickly | G15: 3) I'd stay with them so they don't feel alone | H15: 4) I'd want to understand exactly what happened first | I15: 5) I'd suggest something fun to take their mind off it | J15: D | K15: E | L15: F | M15: G | N15: H | P15: =IF(O15="","",INDEX(J15:N15,1,O15))
A16: Set 1 | B16: Q10 | C16: Making something | D16: Pick a weekend project you'd enjoy making or building. | E16: 1) Building or repairing a gadget/model | F16: 2) Coding a small app or game | G16: 3) Making a health-awareness poster or first-aid kit | H16: 4) Running a small experiment or data project | I16: 5) Organising a fun event or activity for others | J16: A | K16: B | L16: C | M16: G | N16: H | P16: =IF(O16="","",INDEX(J16:N16,1,O16))
A17: Set 1 | B17: Q11 | C17: Wanting to be known for | D17: What would you like to be known for when you grow up? | E17: 1) "Created a widely-used app or game" | F17: 2) "Helped people stay healthy or heal" | G17: 3) "Made art or music that moved people" | H17: 4) "Built a thriving business" | I17: 5) "Made a real difference in my community" | J17: B | K17: C | L17: D | M17: E | N17: F | P17: =IF(O17="","",INDEX(J17:N17,1,O17))
A18: Set 1 | B18: Q12 | C18: Problem you'd like to solve | D18: Which of these problems would you actually enjoy digging into? | E18: 1) How to design something sturdier, faster, or more efficient | F18: 2) How to turn an idea into money | G18: 3) How to make something fairer for a group of people | H18: 4) How something in nature or science actually works | I18: 5) How to make an event or experience more exciting | J18: A | K18: E | L18: F | M18: G | N18: H | P18: =IF(O18="","",INDEX(J18:N18,1,O18))
A19: Set 1 | B19: Q13 | C19: A day in your life at 25 | D19: Imagine yourself at age 25 — what does your workday look like? | E19: 1) Working on-site with machines, tools, or infrastructure | F19: 2) Coding, building products, or managing tech systems | G19: 3) Working in a hospital, clinic, or health-tech company | H19: 4) Creating art, music, films, or content | I19: 5) Coaching sports or managing hospitality/travel | J19: A | K19: B | L19: C | M19: D | N19: H | P19: =IF(O19="","",INDEX(J19:N19,1,O19))
A20: Set 1 | B20: Q14 | C20: When something breaks | D20: Imagine something at home stops working, what do you want to do? | E20: 1) I make sure no one was put at risk | F20: 2) I see if I can creatively repurpose or fix it up | G20: 3) I weigh whether repairing or replacing makes more sense | H20: 4) I let the right people know so it gets handled | I20: 5) I want to understand the root cause before fixing it | J20: C | K20: D | L20: E | M20: F | N20: G | P20: =IF(O20="","",INDEX(J20:N20,1,O20))
A21: Set 1 | B21: Q15 | C21: Role in a team activity | D21: In a class team activity, what part do you enjoy most? | E21: 1) I like building, assembling, or setting things up | F21: 2) I like managing the tech or digital side of things | G21: 3) I like making sure everyone feels included | H21: 4) I like nailing down the facts and rules | I21: 5) I like keeping the group's energy and morale up | J21: A | K21: B | L21: F | M21: G | N21: H | P21: =IF(O21="","",INDEX(J21:N21,1,O21))
A22: Set 2 | B22: Q1 | C22: Free time choice | D22: You have an unplanned afternoon after school. What sounds most appealing? | E22: 1) Sketch, write lyrics, or edit a short video | F22: 2) Plan a small sale or fundraiser with friends | G22: 3) Organise a hangout or help a junior with homework | H22: 4) Watch a science documentary or try a home experiment | I22: 5) Play a match, watch sport, or plan a weekend trip | J22: D | K22: E | L22: F | M22: G | N22: H | P22: =IF(O22="","",INDEX(J22:N22,1,O22))
A23: Set 2 | B23: Q2 | C23: Favorite subject | D23: If you had to pick just one subject to study all day, which would it be? | E23: 1) Workshop, hands-on lab, or technical drawing | F23: 2) Computer Science or coding electives | G23: 3) Biology or Health Science | H23: 4) Physics/Chemistry lab or environmental science | I23: 5) Physical Education or sports coaching sessions | J23: A | K23: B | L23: C | M23: G | N23: H | P23: =IF(O23="","",INDEX(J23:N23,1,O23))
A24: Set 2 | B24: Q3 | C24: Dream job for a day | D24: Which job would you want to try out for a school career-exposure day? | E24: 1) Mobile App Developer or Game Designer | F24: 2) Doctor or Sports Physiotherapist | G24: 3) Animator, Musician, or Content Creator | H24: 4) Entrepreneur or Marketing Manager | I24: 5) Teacher or Counselor | J24: B | K24: C | L24: D | M24: E | N24: F | P24: =IF(O24="","",INDEX(J24:N24,1,O24))
A25: Set 2 | B25: Q4 | C25: Group project role | D25: When your class is split into teams, what job do you usually end up doing? | E25: 1) The one who builds or assembles the physical model | F25: 2) The one who leads, pitches, and presents | G25: 3) The one who makes sure everyone is included and heard | H25: 4) The one who researches facts and checks accuracy | I25: 5) The one who organizes logistics and keeps energy up | J25: A | K25: E | L25: F | M25: G | N25: H | P25: =IF(O25="","",INDEX(J25:N25,1,O25))
A26: Set 2 | B26: Q5 | C26: Dream club or program | D26: If your school offered one special weekend workshop, which would you attend? | E26: 1) Weekend Robotics or Automotive Workshop | F26: 2) Coding Bootcamp or Game Development Club | G26: 3) Junior Medical / First-Responder Program | H26: 4) Music, Art, or Film-making Workshop | I26: 5) Sports Academy Trial or Adventure Camp | J26: A | K26: B | L26: C | M26: D | N26: H | P26: =IF(O26="","",INDEX(J26:N26,1,O26))
... A156: Set 10 | B156: Q15 | C156: Role in a team activity | D156: During a school fair, which job would you sign up for? | E156: 1) I like building, assembling, or setting things up | F156: 2) I like managing the tech or digital side of things | G156: 3) I like making sure everyone feels included | H156: 4) I like nailing down the facts and rules | I156: 5) I like keeping the group's energy and morale up | J156: A | K156: B | L156: F | M156: G | N156: H | P156: =IF(O156="","",INDEX(J156:N156,1,O156))
A158: LIVE RESULTS FOR YOUR SELECTED SET
A159: Cluster (Letter) | B159: Times Chosen | C159: Times It Appeared | D159: Your Score %
A160: A | B160: =COUNTIFS($A$7:$A$156,B4,$P$7:$P$156,"A") -> 0 | C160: =SUMPRODUCT((J7:J156="A")*(A7:A156=B4)+(K7:K156="A")*(A7:A156=B4)+(L7:L156="A")*(A7:A156=B4)+(M7:M156="A")*(A7:A156=B4)+(N7:N156="A")*(A7:A156=B4)) -> 9 | D160: =IFERROR(ROUND(B160/C160*100,0),0) -> 0
A161: B | B161: =COUNTIFS($A$7:$A$156,B4,$P$7:$P$156,"B") -> 0 | C161: =SUMPRODUCT((J7:J156="B")*(A7:A156=B4)+(K7:K156="B")*(A7:A156=B4)+(L7:L156="B")*(A7:A156=B4)+(M7:M156="B")*(A7:A156=B4)+(N7:N156="B")*(A7:A156=B4)) -> 9 | D161: =IFERROR(ROUND(B161/C161*100,0),0) -> 0
A162: C | B162: =COUNTIFS($A$7:$A$156,B4,$P$7:$P$156,"C") -> 0 | C162: =SUMPRODUCT((J7:J156="C")*(A7:A156=B4)+(K7:K156="C")*(A7:A156=B4)+(L7:L156="C")*(A7:A156=B4)+(M7:M156="C")*(A7:A156=B4)+(N7:N156="C")*(A7:A156=B4)) -> 9 | D162: =IFERROR(ROUND(B162/C162*100,0),0) -> 0
A163: D | B163: =COUNTIFS($A$7:$A$156,B4,$P$7:$P$156,"D") -> 0 | C163: =SUMPRODUCT((J7:J156="D")*(A7:A156=B4)+(K7:K156="D")*(A7:A156=B4)+(L7:L156="D")*(A7:A156=B4)+(M7:M156="D")*(A7:A156=B4)+(N7:N156="D")*(A7:A156=B4)) -> 9 | D163: =IFERROR(ROUND(B163/C163*100,0),0) -> 0
A164: E | B164: =COUNTIFS($A$7:$A$156,B4,$P$7:$P$156,"E") -> 0 | C164: =SUMPRODUCT((J7:J156="E")*(A7:A156=B4)+(K7:K156="E")*(A7:A156=B4)+(L7:L156="E")*(A7:A156=B4)+(M7:M156="E")*(A7:A156=B4)+(N7:N156="E")*(A7:A156=B4)) -> 9 | D164: =IFERROR(ROUND(B164/C164*100,0),0) -> 0
A165: F | B165: =COUNTIFS($A$7:$A$156,B4,$P$7:$P$156,"F") -> 0 | C165: =SUMPRODUCT((J7:J156="F")*(A7:A156=B4)+(K7:K156="F")*(A7:A156=B4)+(L7:L156="F")*(A7:A156=B4)+(M7:M156="F")*(A7:A156=B4)+(N7:N156="F")*(A7:A156=B4)) -> 10 | D165: =IFERROR(ROUND(B165/C165*100,0),0) -> 0
A166: G | B166: =COUNTIFS($A$7:$A$156,B4,$P$7:$P$156,"G") -> 0 | C166: =SUMPRODUCT((J7:J156="G")*(A7:A156=B4)+(K7:K156="G")*(A7:A156=B4)+(L7:L156="G")*(A7:A156=B4)+(M7:M156="G")*(A7:A156=B4)+(N7:N156="G")*(A7:A156=B4)) -> 10 | D166: =IFERROR(ROUND(B166/C166*100,0),0) -> 0
A167: H | B167: =COUNTIFS($A$7:$A$156,B4,$P$7:$P$156,"H") -> 0 | C167: =SUMPRODUCT((J7:J156="H")*(A7:A156=B4)+(K7:K156="H")*(A7:A156=B4)+(L7:L156="H")*(A7:A156=B4)+(M7:M156="H")*(A7:A156=B4)+(N7:N156="H")*(A7:A156=B4)) -> 10 | D167: =IFERROR(ROUND(B167/C167*100,0),0) -> 0
A169: YOUR TOP 3 CAREER FIELD MATCHES
A170: Rank | B170: Career Field | C170: Match | D170: Sample Pathways
A171: 1 | B171: =INDEX('Career Clusters & Pathways'!$B$4:$B$11,MATCH(U171,'Career Clusters & Pathways'!$A$4:$A$11,0)) -> Engineering & Construction | C171: =ROUND(LARGE($S$7:$S$14,1),0)&"%" -> 0% | D171: =INDEX('Career Clusters & Pathways'!$D$4:$D$11,MATCH(U171,'Career Clusters & Pathways'!$A$4:$A$11,0)) -> Civil / Structural Engineer, Construction Manager, Industrial / Manufacturing Engineer, Renewable Energy Engineer, Supply Chain / Logistics Manager | U171: =INDEX($R$7:$R$14,MATCH(LARGE($S$7:$S$14,1),$S$7:$S$14,0)) -> A
A172: 2 | B172: =INDEX('Career Clusters & Pathways'!$B$4:$B$11,MATCH(U172,'Career Clusters & Pathways'!$A$4:$A$11,0)) -> Information Technology | C172: =ROUND(LARGE($S$7:$S$14,2),0)&"%" -> 0% | D172: =INDEX('Career Clusters & Pathways'!$D$4:$D$11,MATCH(U172,'Career Clusters & Pathways'!$A$4:$A$11,0)) -> Software Developer, Data Scientist / Analyst, Cybersecurity Analyst, Cloud / DevOps Engineer, UI/UX Designer | U172: =INDEX($R$7:$R$14,MATCH(LARGE($S$7:$S$14,2),$S$7:$S$14,0)) -> B
A173: 3 | B173: =INDEX('Career Clusters & Pathways'!$B$4:$B$11,MATCH(U173,'Career Clusters & Pathways'!$A$4:$A$11,0)) -> Health Science | C173: =ROUND(LARGE($S$7:$S$14,3),0)&"%" -> 0% | D173: =INDEX('Career Clusters & Pathways'!$D$4:$D$11,MATCH(U173,'Career Clusters & Pathways'!$A$4:$A$11,0)) -> Doctor / Dentist, Nurse, Physiotherapist / Allied Health, Pharmacist / Biotech Researcher, Psychologist / Counselor | U173: =INDEX($R$7:$R$14,MATCH(LARGE($S$7:$S$14,3),$S$7:$S$14,0)) -> C
...

Sheet 11-12 Quiz
A1: Class 11-12 (Ages 16-17) — Career Interest Quiz (10 Sets x 15 Questions)
A2: Framework basis: Holland's SDS / Strong Interest Inventory style
A4: Which set are you taking? | B4: Set 1 | C4: (pick one set, then answer only that set's 15 rows below)
A6: Set | B6: Q# | C6: Theme | D6: Scenario | E6: Option 1 | F6: Option 2 | G6: Option 3 | H6: Option 4 | I6: Option 5 | J6: t1 | K6: t2 | L6: t3 | M6: t4 | N6: t5 | O6: Your Answer (1-5) | P6: Letter | R6: Letter | S6: Score
A7: Set 1 | B7: Q1 | C7: Free time choice | D7: You have an unplanned free day before exams start. What do you gravitate toward? | E7: 1) Work on a creative piece (art, music, writing, film) | F7: 2) Test a small resale or business idea online | G7: 3) Mentor a junior student or organise a community drive | H7: 4) Read a science article or run a home experiment | I7: 5) Train for a sport or plan a group trip | J7: D | K7: E | L7: F | M7: G | N7: H | P7: =IF(O7="","",INDEX(J7:N7,1,O7)) | R7: A | S7: =$D$160+0.0000008 -> 8e-07
A8: Set 1 | B8: Q2 | C8: Favorite subject or stream area | D8: Which subject area sounds most exciting to you? | E8: 1) Engineering drawing, applied physics, or a technical elective | F8: 2) Computer Science, programming, or a tech elective | G8: 3) Biology, human physiology, or a pre-med elective | H8: 4) Advanced chemistry, environmental science, or a research elective | I8: 5) Sports science, physical education, or event-management elective | J8: A | K8: B | L8: C | M8: G | N8: H | P8: =IF(O8="","",INDEX(J8:N8,1,O8)) | R8: B | S8: =$D$161+0.0000007 -> 7e-07
A9: Set 1 | B9: Q3 | C9: Dream job for a day | D9: If you could shadow any professional for a day, who would you choose? | E9: 1) App Developer or Game Designer | F9: 2) Surgeon or Sports Physiotherapist | G9: 3) Film Editor, Musician, or UX Designer | H9: 4) Startup Founder or Brand Manager | I9: 5) School Counselor or Policy Researcher | J9: B | K9: C | L9: D | M9: E | N9: F | P9: =IF(O9="","",INDEX(J9:N9,1,O9)) | R9: C | S9: =$D$162+0.0000006 -> 6e-07
A10: Set 1 | B10: Q4 | C10: Group project role | D10: In a group project, what role do you naturally take? | E10: 1) The one who prototypes or physically builds the solution | F10: 2) The one who pitches the idea and drives momentum | G10: 3) The one who makes sure quieter voices get heard | H10: 4) The one who fact-checks and validates the research | I10: 5) The one who runs logistics and keeps morale up | J10: A | K10: E | L10: F | M10: G | N10: H | P10: =IF(O10="","",INDEX(J10:N10,1,O10)) | R10: D | S10: =$D$163+0.0000005 -> 5e-07
A11: Set 1 | B11: Q5 | C11: Dream club or program | D11: Which of these sounds like the club you'd want to join this year? | E11: 1) Pre-college Engineering Bootcamp or Maker Workshop | F11: 2) App Development Bootcamp or Hackathon Prep | G11: 3) Hospital Shadowing or Pre-Med Summer Program | H11: 4) Portfolio-building Workshop (art/film/design) | I11: 5) Sports Talent Camp or Event Management Workshop | J11: A | K11: B | L11: C | M11: D | N11: H | P11: =IF(O11="","",INDEX(J11:N11,1,O11)) | R11: E | S11: =$D$164+0.0000004 -> 4e-07
A12: Set 1 | B12: Q6 | C12: App or tool style | D12: What kind of apps or tools do you use the most? | E12: 1) Health/fitness tracking or telemedicine apps | F12: 2) Design, video-editing, or music-production apps | G12: 3) Stock market or budgeting/investing apps | H12: 4) Volunteering or community-organising apps | I12: 5) Research, data, or citizen-science apps | J12: C | K12: D | L12: E | M12: F | N12: G | P12: =IF(O12="","",INDEX(J12:N12,1,O12)) | R12: F | S12: =$D$165+0.0000003 -> 3e-07
A13: Set 1 | B13: Q7 | C13: Story or show style | D13: What kind of shows or movies do you enjoy most? | E13: 1) Engineering feats, heist, or survival-build stories | F13: 2) Tech-thriller, hacking, or AI-focused stories | G13: 3) Social-justice documentaries or activism stories | H13: 4) Space exploration or nature documentaries | I13: 5) Sports biopics or travel/adventure docuseries | J13: A | K13: B | L13: F | M13: G | N13: H | P13: =IF(O13="","",INDEX(J13:N13,1,O13)) | R13: G | S13: =$D$166+0.0000002 -> 2e-07
A14: Set 1 | B14: Q8 | C14: Career fair booth | D14: If your school ran a career fair, which booth excites you most? | E14: 1) Engineering college or infrastructure-firm booth | F14: 2) Tech company or coding-bootcamp booth | G14: 3) Medical/nursing college booth | H14: 4) Design or film school booth | I14: 5) Business school or startup-incubator booth | J14: A | K14: B | L14: C | M14: D | N14: E | P14: =IF(O14="","",INDEX(J14:N14,1,O14)) | R14: H | S14: =$D$167+0.0000001 -> 1e-07
A15: Set 1 | B15: Q9 | C15: Helping someone | D15: A friend is struggling and clearly not okay. What's your instinct? | E15: 1) I'd express support through something creative | F15: 2) I'd coordinate others to help solve it faster | G15: 3) I'd focus on making sure they feel heard and supported | H15: 4) I'd want to understand the root cause before responding | I15: 5) I'd try to lighten the mood while helping | J15: D | K15: E | L15: F | M15: G | N15: H | P15: =IF(O15="","",INDEX(J15:N15,1,O15))
A16: Set 1 | B16: Q10 | C16: Making something | D16: Pick a weekend project you'd enjoy making or building. | E16: 1) Building or prototyping a working model | F16: 2) Coding an app, script, or small tool | G16: 3) Creating health-awareness content or a first-aid guide | H16: 4) Running an experiment or independent research project | I16: 5) Organising an event, tournament, or trip | J16: A | K16: B | L16: C | M16: G | N16: H | P16: =IF(O16="","",INDEX(J16:N16,1,O16))
A17: Set 1 | B17: Q11 | C17: Wanting to be known for | D17: What would you like to be known for as an adult? | E17: 1) "Built technology that people rely on" | F17: 2) "Helped people live healthier lives" | G17: 3) "Created work that moved or inspired people" | H17: 4) "Built something entrepreneurial from scratch" | I17: 5) "Made a lasting difference in people's lives" | J17: B | K17: C | L17: D | M17: E | N17: F | P17: =IF(O17="","",INDEX(J17:N17,1,O17))
A18: Set 1 | B18: Q12 | C18: Problem you'd like to solve | D18: If you had to pick a research topic purely on interest, which problem would you choose? | E18: 1) How to make a structure or system stronger and more efficient | F18: 2) How to make a product or idea financially viable | G18: 3) How to fix an unfair system or policy | H18: 4) How a natural or scientific phenomenon actually works | I18: 5) How to design a more memorable event or experience | J18: A | K18: E | L18: F | M18: G | N18: H | P18: =IF(O18="","",INDEX(J18:N18,1,O18))
A19: Set 1 | B19: Q13 | C19: A day in your life at 28 | D19: Imagine yourself at age 28 — what does your workday look like? | E19: 1) Leading engineering or infrastructure projects on-site | F19: 2) Building or scaling software products | G19: 3) Practicing medicine or working in health-tech | H19: 4) Working as a creative professional (design, film, writing) | I19: 5) Managing sports programs or hospitality operations | J19: A | K19: B | L19: C | M19: D | N19: H | P19: =IF(O19="","",INDEX(J19:N19,1,O19))
A20: Set 1 | B20: Q14 | C20: When something breaks | D20: Imagine something at home stops working, what do you want to do? | E20: 1) I check whether anyone's safety or wellbeing was affected | F20: 2) I look for a creative workaround or redesign | G20: 3) I weigh the cost of repair versus replacement | H20: 4) I flag it to the right people so it gets resolved | I20: 5) I want a clear root-cause explanation before acting | J20: C | K20: D | L20: E | M20: F | N20: G | P20: =IF(O20="","",INDEX(J20:N20,1,O20))
A21: Set 1 | B21: Q15 | C21: Role in a team activity | D21: In a class team activity, what part do you enjoy most? | E21: 1) I like building, prototyping, or physically setting things up | F21: 2) I like owning the tech or digital execution | G21: 3) I like making sure everyone's voice is heard | H21: 4) I like verifying facts and keeping things accurate | I21: 5) I like keeping morale and energy high | J21: A | K21: B | L21: F | M21: G | N21: H | P21: =IF(O21="","",INDEX(J21:N21,1,O21))
A22: Set 2 | B22: Q1 | C22: Free time choice | D22: You have an unplanned afternoon between coaching classes. What sounds most appealing? | E22: 1) Work on a creative piece (art, music, writing, film) | F22: 2) Test a small resale or business idea online | G22: 3) Mentor a junior student or organise a community drive | H22: 4) Read a science article or run a home experiment | I22: 5) Train for a sport or plan a group trip | J22: D | K22: E | L22: F | M22: G | N22: H | P22: =IF(O22="","",INDEX(J22:N22,1,O22))
A23: Set 2 | B23: Q2 | C23: Favorite subject or stream area | D23: If you had to pick just one subject to study all day, which would it be? | E23: 1) Engineering drawing, applied physics, or a technical elective | F23: 2) Computer Science, programming, or a tech elective | G23: 3) Biology, human physiology, or a pre-med elective | H23: 4) Advanced chemistry, environmental science, or a research elective | I23: 5) Sports science, physical education, or event-management elective | J23: A | K23: B | L23: C | M23: G | N23: H | P23: =IF(O23="","",INDEX(J23:N23,1,O23))
A24: Set 2 | B24: Q3 | C24: Dream job for a day | D24: Which job would you want to try during a school career-exposure program? | E24: 1) App Developer or Game Designer | F24: 2) Surgeon or Sports Physiotherapist | G24: 3) Film Editor, Musician, or UX Designer | H24: 4) Startup Founder or Brand Manager | I24: 5) School Counselor or Policy Researcher | J24: B | K24: C | L24: D | M24: E | N24: F | P24: =IF(O24="","",INDEX(J24:N24,1,O24))
A25: Set 2 | B25: Q4 | C25: Group project role | D25: When your class is split into teams, what job do you usually end up doing? | E25: 1) The one who prototypes or physically builds the solution | F25: 2) The one who pitches the idea and drives momentum | G25: 3) The one who makes sure quieter voices get heard | H25: 4) The one who fact-checks and validates the research | I25: 5) The one who runs logistics and keeps morale up | J25: A | K25: E | L25: F | M25: G | N25: H | P25: =IF(O25="","",INDEX(J25:N25,1,O25))
A26: Set 2 | B26: Q5 | C26: Dream club or program | D26: If your school offered one special weekend workshop, which would you attend? | E26: 1) Pre-college Engineering Bootcamp or Maker Workshop | F26: 2) App Development Bootcamp or Hackathon Prep | G26: 3) Hospital Shadowing or Pre-Med Summer Program | H26: 4) Portfolio-building Workshop (art/film/design) | I26: 5) Sports Talent Camp or Event Management Workshop | J26: A | K26: B | L26: C | M26: D | N26: H | P26: =IF(O26="","",INDEX(J26:N26,1,O26))
... A156: Set 10 | B156: Q15 | C156: Role in a team activity | D156: During a school fair, which job would you sign up for? | E156: 1) I like building, prototyping, or physically setting things up | F156: 2) I like owning the tech or digital execution | G156: 3) I like making sure everyone's voice is heard | H156: 4) I like verifying facts and keeping things accurate | I156: 5) I like keeping morale and energy high | J156: A | K156: B | L156: F | M156: G | N156: H | P156: =IF(O156="","",INDEX(J156:N156,1,O156))
A158: LIVE RESULTS FOR YOUR SELECTED SET
A159: Cluster (Letter) | B159: Times Chosen | C159: Times It Appeared | D159: Your Score %
A160: A | B160: =COUNTIFS($A$7:$A$156,B4,$P$7:$P$156,"A") -> 0 | C160: =SUMPRODUCT((J7:J156="A")*(A7:A156=B4)+(K7:K156="A")*(A7:A156=B4)+(L7:L156="A")*(A7:A156=B4)+(M7:M156="A")*(A7:A156=B4)+(N7:N156="A")*(A7:A156=B4)) -> 9 | D160: =IFERROR(ROUND(B160/C160*100,0),0) -> 0
A161: B | B161: =COUNTIFS($A$7:$A$156,B4,$P$7:$P$156,"B") -> 0 | C161: =SUMPRODUCT((J7:J156="B")*(A7:A156=B4)+(K7:K156="B")*(A7:A156=B4)+(L7:L156="B")*(A7:A156=B4)+(M7:M156="B")*(A7:A156=B4)+(N7:N156="B")*(A7:A156=B4)) -> 9 | D161: =IFERROR(ROUND(B161/C161*100,0),0) -> 0
A162: C | B162: =COUNTIFS($A$7:$A$156,B4,$P$7:$P$156,"C") -> 0 | C162: =SUMPRODUCT((J7:J156="C")*(A7:A156=B4)+(K7:K156="C")*(A7:A156=B4)+(L7:L156="C")*(A7:A156=B4)+(M7:M156="C")*(A7:A156=B4)+(N7:N156="C")*(A7:A156=B4)) -> 9 | D162: =IFERROR(ROUND(B162/C162*100,0),0) -> 0
A163: D | B163: =COUNTIFS($A$7:$A$156,B4,$P$7:$P$156,"D") -> 0 | C163: =SUMPRODUCT((J7:J156="D")*(A7:A156=B4)+(K7:K156="D")*(A7:A156=B4)+(L7:L156="D")*(A7:A156=B4)+(M7:M156="D")*(A7:A156=B4)+(N7:N156="D")*(A7:A156=B4)) -> 9 | D163: =IFERROR(ROUND(B163/C163*100,0),0) -> 0
A164: E | B164: =COUNTIFS($A$7:$A$156,B4,$P$7:$P$156,"E") -> 0 | C164: =SUMPRODUCT((J7:J156="E")*(A7:A156=B4)+(K7:K156="E")*(A7:A156=B4)+(L7:L156="E")*(A7:A156=B4)+(M7:M156="E")*(A7:A156=B4)+(N7:N156="E")*(A7:A156=B4)) -> 9 | D164: =IFERROR(ROUND(B164/C164*100,0),0) -> 0
A165: F | B165: =COUNTIFS($A$7:$A$156,B4,$P$7:$P$156,"F") -> 0 | C165: =SUMPRODUCT((J7:J156="F")*(A7:A156=B4)+(K7:K156="F")*(A7:A156=B4)+(L7:L156="F")*(A7:A156=B4)+(M7:M156="F")*(A7:A156=B4)+(N7:N156="F")*(A7:A156=B4)) -> 10 | D165: =IFERROR(ROUND(B165/C165*100,0),0) -> 0
A166: G | B166: =COUNTIFS($A$7:$A$156,B4,$P$7:$P$156,"G") -> 0 | C166: =SUMPRODUCT((J7:J156="G")*(A7:A156=B4)+(K7:K156="G")*(A7:A156=B4)+(L7:L156="G")*(A7:A156=B4)+(M7:M156="G")*(A7:A156=B4)+(N7:N156="G")*(A7:A156=B4)) -> 10 | D166: =IFERROR(ROUND(B166/C166*100,0),0) -> 0
A167: H | B167: =COUNTIFS($A$7:$A$156,B4,$P$7:$P$156,"H") -> 0 | C167: =SUMPRODUCT((J7:J156="H")*(A7:A156=B4)+(K7:K156="H")*(A7:A156=B4)+(L7:L156="H")*(A7:A156=B4)+(M7:M156="H")*(A7:A156=B4)+(N7:N156="H")*(A7:A156=B4)) -> 10 | D167: =IFERROR(ROUND(B167/C167*100,0),0) -> 0
A169: YOUR TOP 3 CAREER FIELD MATCHES
A170: Rank | B170: Career Field | C170: Match | D170: Sample Pathways
A171: 1 | B171: =INDEX('Career Clusters & Pathways'!$B$4:$B$11,MATCH(U171,'Career Clusters & Pathways'!$A$4:$A$11,0)) -> Engineering & Construction | C171: =ROUND(LARGE($S$7:$S$14,1),0)&"%" -> 0% | D171: =INDEX('Career Clusters & Pathways'!$D$4:$D$11,MATCH(U171,'Career Clusters & Pathways'!$A$4:$A$11,0)) -> Civil / Structural Engineer, Construction Manager, Industrial / Manufacturing Engineer, Renewable Energy Engineer, Supply Chain / Logistics Manager | U171: =INDEX($R$7:$R$14,MATCH(LARGE($S$7:$S$14,1),$S$7:$S$14,0)) -> A
A172: 2 | B172: =INDEX('Career Clusters & Pathways'!$B$4:$B$11,MATCH(U172,'Career Clusters & Pathways'!$A$4:$A$11,0)) -> Information Technology | C172: =ROUND(LARGE($S$7:$S$14,2),0)&"%" -> 0% | D172: =INDEX('Career Clusters & Pathways'!$D$4:$D$11,MATCH(U172,'Career Clusters & Pathways'!$A$4:$A$11,0)) -> Software Developer, Data Scientist / Analyst, Cybersecurity Analyst, Cloud / DevOps Engineer, UI/UX Designer | U172: =INDEX($R$7:$R$14,MATCH(LARGE($S$7:$S$14,2),$S$7:$S$14,0)) -> B
A173: 3 | B173: =INDEX('Career Clusters & Pathways'!$B$4:$B$11,MATCH(U173,'Career Clusters & Pathways'!$A$4:$A$11,0)) -> Health Science | C173: =ROUND(LARGE($S$7:$S$14,3),0)&"%" -> 0% | D173: =INDEX('Career Clusters & Pathways'!$D$4:$D$11,MATCH(U173,'Career Clusters & Pathways'!$A$4:$A$11,0)) -> Doctor / Dentist, Nurse, Physiotherapist / Allied Health, Pharmacist / Biotech Researcher, Psychologist / Counselor | U173: =INDEX($R$7:$R$14,MATCH(LARGE($S$7:$S$14,3),$S$7:$S$14,0)) -> C
...

Sheet Grad Quiz
A1: Graduate (Ages 18-21) — Career Interest Quiz (10 Sets x 15 Questions)
A2: Framework basis: Holland's SDS / Strong Interest Inventory style
A4: Which set are you taking? | B4: Set 1 | C4: (pick one set, then answer only that set's 15 rows below)
A6: Set | B6: Q# | C6: Theme | D6: Scenario | E6: Option 1 | F6: Option 2 | G6: Option 3 | H6: Option 4 | I6: Option 5 | J6: t1 | K6: t2 | L6: t3 | M6: t4 | N6: t5 | O6: Your Answer (1-5) | P6: Letter | R6: Letter | S6: Score
A7: Set 1 | B7: Q1 | C7: Free time choice | D7: You have a free Saturday with no assignments due. What do you spend it on? | E7: 1) Work on a creative portfolio piece (design, music, writing, film) | F7: 2) Test a small business, resale, or freelance gig idea | G7: 3) Volunteer, tutor, or help organise a student event | H7: 4) Read a research paper or run a small experiment/analysis | I7: 5) Train for a sport, plan a trip, or explore a new city | J7: D | K7: E | L7: F | M7: G | N7: H | P7: =IF(O7="","",INDEX(J7:N7,1,O7)) | R7: A | S7: =$D$160+0.0000008 -> 8e-07
A8: Set 1 | B8: Q2 | C8: Favorite subject or coursework | D8: Which subject area sounds most exciting to you? | E8: 1) A hands-on engineering lab or workshop course | F8: 2) A programming, data structures, or software course | G8: 3) A human biology, anatomy, or public-health course | H8: 4) A core science, research-methods, or environmental course | I8: 5) A sports-management or hospitality-focused course | J8: A | K8: B | L8: C | M8: G | N8: H | P8: =IF(O8="","",INDEX(J8:N8,1,O8)) | R8: B | S8: =$D$161+0.0000007 -> 7e-07
A9: Set 1 | B9: Q3 | C9: Dream job for a day | D9: If you could shadow any professional for a day, who would you choose? | E9: 1) Full-Stack Developer or Data Scientist | F9: 2) Junior Doctor or Clinical Researcher | G9: 3) Creative Director or Independent Filmmaker | H9: 4) Startup Co-Founder or Brand Strategist | I9: 5) NGO Program Officer or Policy Analyst | J9: B | K9: C | L9: D | M9: E | N9: F | P9: =IF(O9="","",INDEX(J9:N9,1,O9)) | R9: C | S9: =$D$162+0.0000006 -> 6e-07
A10: Set 1 | B10: Q4 | C10: Group project role | D10: In a group project, what role do you naturally take? | E10: 1) The one who builds the working prototype | F10: 2) The one who pitches to stakeholders and drives direction | G10: 3) The one who resolves conflicts and keeps the team aligned | H10: 4) The one who validates data and checks assumptions | I10: 5) The one who manages timelines and keeps energy up | J10: A | K10: E | L10: F | M10: G | N10: H | P10: =IF(O10="","",INDEX(J10:N10,1,O10)) | R10: D | S10: =$D$163+0.0000005 -> 5e-07
A11: Set 1 | B11: Q5 | C11: Dream club or program | D11: Which of these sounds like the society you'd want to join this year? | E11: 1) Manufacturing/Robotics Internship or Maker-space Residency | F11: 2) Software Development Bootcamp or Open-Source Sprint | G11: 3) Clinical Shadowing Program or Public Health Fellowship | H11: 4) Design/Film Residency or Creative Portfolio Bootcamp | I11: 5) Sports Management Internship or Hospitality Trainee Program | J11: A | K11: B | L11: C | M11: D | N11: H | P11: =IF(O11="","",INDEX(J11:N11,1,O11)) | R11: E | S11: =$D$164+0.0000004 -> 4e-07
A12: Set 1 | B12: Q6 | C12: App or tool style | D12: What kind of apps or tools do you use the most? | E12: 1) Health/fitness apps or telemedicine platforms | F12: 2) Design, video-editing, or music-production software | G12: 3) Investing, budgeting, or startup-pitch tools | H12: 4) Volunteering platforms or community-organising apps | I12: 5) Data analysis or research/citation tools | J12: C | K12: D | L12: E | M12: F | N12: G | P12: =IF(O12="","",INDEX(J12:N12,1,O12)) | R12: F | S12: =$D$165+0.0000003 -> 3e-07
A13: Set 1 | B13: Q7 | C13: Story or show style | D13: What kind of shows or movies do you enjoy most? | E13: 1) Engineering marvels or survival/build documentaries | F13: 2) Tech-industry dramas or hacking thrillers | G13: 3) Social-impact documentaries or activism stories | H13: 4) Space, climate, or nature documentaries | I13: 5) Sports documentaries or travel/adventure series | J13: A | K13: B | L13: F | M13: G | N13: H | P13: =IF(O13="","",INDEX(J13:N13,1,O13)) | R13: G | S13: =$D$166+0.0000002 -> 2e-07
A14: Set 1 | B14: Q8 | C14: Career fair booth | D14: If your college ran a placement or career fair, which booth excites you most? | E14: 1) Infrastructure/manufacturing recruiter booth | F14: 2) Tech company or product-company booth | G14: 3) Hospital network or health-tech recruiter booth | H14: 4) Media/design agency or studio booth | I14: 5) Consulting firm or startup recruiter booth | J14: A | K14: B | L14: C | M14: D | N14: E | P14: =IF(O14="","",INDEX(J14:N14,1,O14)) | R14: H | S14: =$D$167+0.0000001 -> 1e-07
A15: Set 1 | B15: Q9 | C15: Helping someone | D15: A coursemate is going through a rough patch. What's your instinct? | E15: 1) I'd offer support through a thoughtful, creative gesture | F15: 2) I'd mobilise friends or resources to help quickly | G15: 3) I'd make sure they have someone to talk to | H15: 4) I'd want a clear, evidence-based understanding of what happened | I15: 5) I'd try to keep their spirits up with humour or distraction | J15: D | K15: E | L15: F | M15: G | N15: H | P15: =IF(O15="","",INDEX(J15:N15,1,O15))
A16: Set 1 | B16: Q10 | C16: Making something | D16: Pick a weekend project you'd enjoy making or building. | E16: 1) Building or prototyping a functional product | F16: 2) Coding a personal project, script, or tool | G16: 3) Creating health/wellness content or a support resource | H16: 4) Running an independent research or data project | I16: 5) Organising an event, trip, or competition | J16: A | K16: B | L16: C | M16: G | N16: H | P16: =IF(O16="","",INDEX(J16:N16,1,O16))
A17: Set 1 | B17: Q11 | C17: Wanting to be known for | D17: What would you like to be known for in your career? | E17: 1) "Built technology that solved a real problem" | F17: 2) "Improved people's health or wellbeing at scale" | G17: 3) "Created work that resonated deeply with people" | H17: 4) "Built a venture from the ground up" | I17: 5) "Made a lasting difference in my community" | J17: B | K17: C | L17: D | M17: E | N17: F | P17: =IF(O17="","",INDEX(J17:N17,1,O17))
A18: Set 1 | B18: Q12 | C18: Problem you'd like to solve | D18: If you had to pick a capstone project topic, which problem would you choose? | E18: 1) How to make a system or structure more efficient | F18: 2) How to make a business model financially sustainable | G18: 3) How to fix an unfair or broken system | H18: 4) How an unexplained scientific phenomenon actually works | I18: 5) How to design a more memorable experience or event | J18: A | K18: E | L18: F | M18: G | N18: H | P18: =IF(O18="","",INDEX(J18:N18,1,O18))
A19: Set 1 | B19: Q13 | C19: A day in your life at 30 | D19: Imagine yourself at age 30 — what does your workday look like? | E19: 1) Leading engineering, construction, or manufacturing projects | F19: 2) Building and scaling software products | G19: 3) Practicing medicine, research, or working in health-tech | H19: 4) Working as an established creative professional | I19: 5) Managing sports, hospitality, or event operations at scale | J19: A | K19: B | L19: C | M19: D | N19: H | P19: =IF(O19="","",INDEX(J19:N19,1,O19))
A20: Set 1 | B20: Q14 | C20: When something breaks | D20: Imagine something at your place stops working, what do you want to do? | E20: 1) I first check whether anyone's safety was put at risk | F20: 2) I look for a creative or redesigned solution | G20: 3) I weigh whether it's worth fixing, replacing, or outsourcing | H20: 4) I escalate it to the right people so it's handled properly | I20: 5) I want to understand the root cause before acting | J20: C | K20: D | L20: E | M20: F | N20: G | P20: =IF(O20="","",INDEX(J20:N20,1,O20))
A21: Set 1 | B21: Q15 | C21: Role in a team activity | D21: In a class team activity, what part do you enjoy most? | E21: 1) I like building or physically executing the plan | F21: 2) I like owning the technical execution | G21: 3) I like making sure quieter voices are heard | H21: 4) I like verifying facts and validating the approach | I21: 5) I like keeping team morale and momentum high | J21: A | K21: B | L21: F | M21: G | N21: H | P21: =IF(O21="","",INDEX(J21:N21,1,O21))
A22: Set 2 | B22: Q1 | C22: Free time choice | D22: You have an unplanned afternoon between classes. What sounds most appealing? | E22: 1) Work on a creative portfolio piece (design, music, writing, film) | F22: 2) Test a small business, resale, or freelance gig idea | G22: 3) Volunteer, tutor, or help organise a student event | H22: 4) Read a research paper or run a small experiment/analysis | I22: 5) Train for a sport, plan a trip, or explore a new city | J22: D | K22: E | L22: F | M22: G | N22: H | P22: =IF(O22="","",INDEX(J22:N22,1,O22))
A23: Set 2 | B23: Q2 | C23: Favorite subject or coursework | D23: If you had to pick just one subject to study all day, which would it be? | E23: 1) A hands-on engineering lab or workshop course | F23: 2) A programming, data structures, or software course | G23: 3) A human biology, anatomy, or public-health course | H23: 4) A core science, research-methods, or environmental course | I23: 5) A sports-management or hospitality-focused course | J23: A | K23: B | L23: C | M23: G | N23: H | P23: =IF(O23="","",INDEX(J23:N23,1,O23))
A24: Set 2 | B24: Q3 | C24: Dream job for a day | D24: Which job would you want to try during a college career-exposure program? | E24: 1) Full-Stack Developer or Data Scientist | F24: 2) Junior Doctor or Clinical Researcher | G24: 3) Creative Director or Independent Filmmaker | H24: 4) Startup Co-Founder or Brand Strategist | I24: 5) NGO Program Officer or Policy Analyst | J24: B | K24: C | L24: D | M24: E | N24: F | P24: =IF(O24="","",INDEX(J24:N24,1,O24))
A25: Set 2 | B25: Q4 | C25: Group project role | D25: When your class is split into teams, what job do you usually end up doing? | E25: 1) The one who builds the working prototype | F25: 2) The one who pitches to stakeholders and drives direction | G25: 3) The one who resolves conflicts and keeps the team aligned | H25: 4) The one who validates data and checks assumptions | I25: 5) The one who manages timelines and keeps energy up | J25: A | K25: E | L25: F | M25: G | N25: H | P25: =IF(O25="","",INDEX(J25:N25,1,O25))
A26: Set 2 | B26: Q5 | C26: Dream club or program | D26: If your college offered one special weekend workshop, which would you attend? | E26: 1) Manufacturing/Robotics Internship or Maker-space Residency | F26: 2) Software Development Bootcamp or Open-Source Sprint | G26: 3) Clinical Shadowing Program or Public Health Fellowship | H26: 4) Design/Film Residency or Creative Portfolio Bootcamp | I26: 5) Sports Management Internship or Hospitality Trainee Program | J26: A | K26: B | L26: C | M26: D | N26: H | P26: =IF(O26="","",INDEX(J26:N26,1,O26))
... A156: Set 10 | B156: Q15 | C156: Role in a team activity | D156: During a college fest, which job would you sign up for? | E156: 1) I like building or physically executing the plan | F156: 2) I like owning the technical execution | G156: 3) I like making sure quieter voices are heard | H156: 4) I like verifying facts and validating the approach | I156: 5) I like keeping team morale and momentum high | J156: A | K156: B | L156: F | M156: G | N156: H | P156: =IF(O156="","",INDEX(J156:N156,1,O156))
A158: LIVE RESULTS FOR YOUR SELECTED SET
A159: Cluster (Letter) | B159: Times Chosen | C159: Times It Appeared | D159: Your Score %
A160: A | B160: =COUNTIFS($A$7:$A$156,B4,$P$7:$P$156,"A") -> 0 | C160: =SUMPRODUCT((J7:J156="A")*(A7:A156=B4)+(K7:K156="A")*(A7:A156=B4)+(L7:L156="A")*(A7:A156=B4)+(M7:M156="A")*(A7:A156=B4)+(N7:N156="A")*(A7:A156=B4)) -> 9 | D160: =IFERROR(ROUND(B160/C160*100,0),0) -> 0
